Workbook

Sheet GVA
D1: GVA FIGURES for cut/paste into grant form
D2: < INSERT CLIENT COMPANY NAME >
B3: Without Grant (BAU) | D3: Baseline | E3: Year 1 | F3: Year 2 | G3: Year 3
A4: Labour | D4: =D19 | E4: =E19 | F4: =F19 | G4: =G19
A5: NPBT £s | D5: =D20 | E5: =E20 | F5: =F20 | G5: =G20
A6: Depreciation £s | D6: =D21 | E6: =E21 | F6: =F21 | G6: =G21
D7: =SUM(D4:D6) | E7: =SUM(E4:E6) | F7: =SUM(F4:F6) | G7: =SUM(G4:G6)
A8: Labour | B8: With Grant (Accelerated) | D8: =D23 | E8: =E23 | F8: =F23 | G8: =G23
A9: NPBT £s | D9: =D24 | E9: =E24 | F9: =F24 | G9: =G24
A10: Depreciation £s | D10: =D25 | E10: =E25 | F10: =F25 | G10: =G25
D11: =SUM(D8:D10) | E11: =SUM(E8:E10) | F11: =SUM(F8:F10) | G11: =SUM(G8:G10)
D12: =D11-D7 | E12: =E11-E7 | F12: =F11-F7 | G12: =G11-G7
B13: TOTAL GVA | D13: =SUM(D12:G12)
D15: GVA "Story" Model (OUTPUT + DEPRECIATION INPUT)
B18: No grant | D18: Baseline | E18: Year 1 | F18: Year 2 | G18: Year 3
B19: Labour | D19: =D36 | E19: =E36 | F19: =F36 | G19: =G36
B20: NPBT | D20: =D38 | E20: =E38 | F20: =F38 | G20: =G38
B21: Depreciation | D21: =E21 | E21: 67284 | F21: 67284 | G21: 67284
B22: w/ grant | D22: =SUM(D19:D21) | E22: =SUM(E19:E21) | F22: =SUM(F19:F21) | G22: =SUM(G19:G21) | H22: (Note: depreciation is handled here because its not modelled, so kept away from the model below
B23: Labour | D23: =D44 | E23: =E44 | F23: =F44 | G23: =G44
B24: NPBT | D24: =D46 | E24: =E46 | F24: =F46 | G24: =G46
B25: Depreciation | D25: =D21 | E25: =$B$31/3+E21 | F25: =B31/3+F21 | G25: =B31/3+G21
D26: =SUM(D23:D25) | E26: =SUM(E23:E25) | F26: =SUM(F23:F25) | G26: =SUM(G23:G25)
D27: =D26-D22 | E27: =E26-E22 | F27: =F26-F22 | G27: =G26-G22
B28: TOTAL GVA | D28: =SUM(D27:G27)
A30: Investment (£) | B30: Project Cost | D30: GVA "Story" Model (GVA LEVER INPUTS)
B31: 40000
D32: Baseline | E32: Year 1 | F32: Year 2 | G32: Year 3
B33: NO GRANT
A34: Av. Cost per | B34: Rev (£, millions) | D34: 1.9 | E34: 2.2 | F34: 2.3 | G34: 2.4
A35: Employee | B35: FTEs | D35: 19 | E35: 20 | F35: 21 | G35: 22
A36: =D36/D35 | B36: Labour (£) | D36: 500000 | E36: =E35*$A$36 | F36: =F35*$A$36 | G36: =G35*$A$36
A37: (sense check this) | B37: NPBT (%) | D37: =D38/D34/1000000 | E37: 0.1 | F37: 0.095 | G37: 0.09
B38: NPBT (£) | D38: 200000 | E38: =E37*E34*1000000 | F38: =F37*F34*1000000 | G38: =G37*G34*1000000
B39: Non-labour cost saving (% points of turnover, calc.) | D39: 0 | E39: =(($D$34*1000000-$D$36-$D$38)/($D$34*1000000))-(E34*1000000-E36-E38)/(E34*1000000) | F39: =(($D$34*1000000-$D$36-$D$38)/($D$34*1000000))-(F34*1000000-F36-F38)/(F34*1000000) | G39: =(($D$34*1000000-$D$36-$D$38)/($D$34*1000000))-(G34*1000000-G36-G38)/(G34*1000000)
B40: Productivity gain vs baseline | E40: =(E34/E35)/($D$34/$D$35)-1 | F40: =(F34/F35)/($D$34/$D$35)-1 | G40: =(G34/G35)/($D$34/$D$35)-1
B41: WITH GRANT
B42: Rev (£, millions) | D42: =D34 | E42: 2.4 | F42: 3 | G42: 3.8
B43: FTEs | D43: =D35 | E43: 24 | F43: 25 | G43: 26
B44: Labour£ | D44: =D36 | E44: =E43*$A$36 | F44: =F43*$A$36 | G44: =G43*$A$36
...

Sheet P&L
B1: PROFIT & LOSS - Without and With Grant | D1: =GVA!D2
B3: WITHOUT GRANT (BAU) | D3: Baseline | E3: Year 1 | F3: Year 2 | G3: Year 3
B4: Turnover | D4: =GVA!D34*1000000 | E4: =GVA!E34*1000000 | F4: =GVA!F34*1000000 | G4: =GVA!G34*1000000
B5: Materials & plant hire | D5: =IFERROR((0.5*GVA!$D$34*1000000-0.7*GVA!$D$36)/(GVA!$D$34*1000000-GVA!$D$36-GVA!$D$38),0)*(D4-GVA!D36-GVA!D38) | E5: =IFERROR((0.5*GVA!$D$34*1000000-0.7*GVA!$D$36)/(GVA!$D$34*1000000-GVA!$D$36-GVA!$D$38),0)*(E4-GVA!E36-GVA!E38) | F5: =IFERROR((0.5*GVA!$D$34*1000000-0.7*GVA!$D$36)/(GVA!$D$34*1000000-GVA!$D$36-GVA!$D$38),0)*(F4-GVA!F36-GVA!F38) | G5: =IFERROR((0.5*GVA!$D$34*1000000-0.7*GVA!$D$36)/(GVA!$D$34*1000000-GVA!$D$36-GVA!$D$38),0)*(G4-GVA!G36-GVA!G38)
B6: % of turnover | D6: =IFERROR(D5/D4,0) | E6: =IFERROR(E5/E4,0) | F6: =IFERROR(F5/F4,0) | G6: =IFERROR(G5/G4,0)
B7: Direct staff cost | D7: =0.7*GVA!D36 | E7: =0.7*GVA!E36 | F7: =0.7*GVA!F36 | G7: =0.7*GVA!G36
B8: % of turnover | D8: =IFERROR(D7/D4,0) | E8: =IFERROR(E7/E4,0) | F8: =IFERROR(F7/F4,0) | G8: =IFERROR(G7/G4,0)
B9: Cost of sales | D9: =D5+D7 | E9: =E5+E7 | F9: =F5+F7 | G9: =G5+G7
B10: % of turnover | D10: =IFERROR(D9/D4,0) | E10: =IFERROR(E9/E4,0) | F10: =IFERROR(F9/F4,0) | G10: =IFERROR(G9/G4,0)
B11: Gross profit | D11: =D4-D9 | E11: =E4-E9 | F11: =F4-F9 | G11: =G4-G9
B12: Gross profit % | D12: =IFERROR(D11/D4,0) | E12: =IFERROR(E11/E4,0) | F12: =IFERROR(F11/F4,0) | G12: =IFERROR(G11/G4,0)
B13: Indirect staff cost | D13: =0.3*GVA!D36 | E13: =0.3*GVA!E36 | F13: =0.3*GVA!F36 | G13: =0.3*GVA!G36
B14: % of turnover | D14: =IFERROR(D13/D4,0) | E14: =IFERROR(E13/E4,0) | F14: =IFERROR(F13/F4,0) | G14: =IFERROR(G13/G4,0)
B15: Indirect costs | D15: =D11-D13-GVA!D38 | E15: =E11-E13-GVA!E38 | F15: =F11-F13-GVA!F38 | G15: =G11-G13-GVA!G38
B16: % of turnover | D16: =IFERROR(D15/D4,0) | E16: =IFERROR(E15/E4,0) | F16: =IFERROR(F15/F4,0) | G16: =IFERROR(G15/G4,0)
B17: Administrative expenses | D17: =D13+D15 | E17: =E13+E15 | F17: =F13+F15 | G17: =G13+G15
B18: % of turnover | D18: =IFERROR(D17/D4,0) | E18: =IFERROR(E17/E4,0) | F18: =IFERROR(F17/F4,0) | G18: =IFERROR(G17/G4,0)
B19: Net profit before tax | D19: =D11-D17 | E19: =E11-E17 | F19: =F11-F17 | G19: =G11-G17
B20: Net profit % | D20: =IFERROR(D19/D4,0) | E20: =IFERROR(E19/E4,0) | F20: =IFERROR(F19/F4,0) | G20: =IFERROR(G19/G4,0)
B21: FTEs | D21: =GVA!D35 | E21: =GVA!E35 | F21: =GVA!F35 | G21: =GVA!G35
B23: WITH GRANT (ACCELERATED) | D23: Baseline | E23: Year 1 | F23: Year 2 | G23: Year 3
B24: Turnover | D24: =GVA!D42*1000000 | E24: =GVA!E42*1000000 | F24: =GVA!F42*1000000 | G24: =GVA!G42*1000000
B25: Materials & plant hire | D25: =IFERROR((0.5*GVA!$D$34*1000000-0.7*GVA!$D$36)/(GVA!$D$34*1000000-GVA!$D$36-GVA!$D$38),0)*(D24-GVA!D44-GVA!D46) | E25: =IFERROR((0.5*GVA!$D$34*1000000-0.7*GVA!$D$36)/(GVA!$D$34*1000000-GVA!$D$36-GVA!$D$38),0)*(E24-GVA!E44-GVA!E46) | F25: =IFERROR((0.5*GVA!$D$34*1000000-0.7*GVA!$D$36)/(GVA!$D$34*1000000-GVA!$D$36-GVA!$D$38),0)*(F24-GVA!F44-GVA!F46) | G25: =IFERROR((0.5*GVA!$D$34*1000000-0.7*GVA!$D$36)/(GVA!$D$34*1000000-GVA!$D$36-GVA!$D$38),0)*(G24-GVA!G44-GVA!G46)
B26: % of turnover | D26: =IFERROR(D25/D24,0) | E26: =IFERROR(E25/E24,0) | F26: =IFERROR(F25/F24,0) | G26: =IFERROR(G25/G24,0)
B27: Direct staff cost | D27: =0.7*GVA!D44 | E27: =0.7*GVA!E44 | F27: =0.7*GVA!F44 | G27: =0.7*GVA!G44
B28: % of turnover | D28: =IFERROR(D27/D24,0) | E28: =IFERROR(E27/E24,0) | F28: =IFERROR(F27/F24,0) | G28: =IFERROR(G27/G24,0)
B29: Cost of sales | D29: =D25+D27 | E29: =E25+E27 | F29: =F25+F27 | G29: =G25+G27
B30: % of turnover | D30: =IFERROR(D29/D24,0) | E30: =IFERROR(E29/E24,0) | F30: =IFERROR(F29/F24,0) | G30: =IFERROR(G29/G24,0)
B31: Gross profit | D31: =D24-D29 | E31: =E24-E29 | F31: =F24-F29 | G31: =G24-G29
B32: Gross profit % | D32: =IFERROR(D31/D24,0) | E32: =IFERROR(E31/E24,0) | F32: =IFERROR(F31/F24,0) | G32: =IFERROR(G31/G24,0)
B33: Indirect staff cost | D33: =0.3*GVA!D44 | E33: =0.3*GVA!E44 | F33: =0.3*GVA!F44 | G33: =0.3*GVA!G44
B34: % of turnover | D34: =IFERROR(D33/D24,0) | E34: =IFERROR(E33/E24,0) | F34: =IFERROR(F33/F24,0) | G34: =IFERROR(G33/G24,0)
B35: Indirect costs | D35: =D31-D33-GVA!D46 | E35: =E31-E33-GVA!E46 | F35: =F31-F33-GVA!F46 | G35: =G31-G33-GVA!G46
B36: % of turnover | D36: =IFERROR(D35/D24,0) | E36: =IFERROR(E35/E24,0) | F36: =IFERROR(F35/F24,0) | G36: =IFERROR(G35/G24,0)
B37: Administrative expenses | D37: =D33+D35 | E37: =E33+E35 | F37: =F33+F35 | G37: =G33+G35
B38: % of turnover | D38: =IFERROR(D37/D24,0) | E38: =IFERROR(E37/E24,0) | F38: =IFERROR(F37/F24,0) | G38: =IFERROR(G37/G24,0)
B39: Net profit before tax | D39: =D31-D37 | E39: =E31-E37 | F39: =F31-F37 | G39: =G31-G37
B40: Net profit % | D40: =IFERROR(D39/D24,0) | E40: =IFERROR(E39/E24,0) | F40: =IFERROR(F39/F24,0) | G40: =IFERROR(G39/G24,0)
B41: FTEs | D41: =GVA!D43 | E41: =GVA!E43 | F41: =GVA!F43 | G41: =GVA!G43
B43: DIFFERENCE (WITH - WITHOUT GRANT) | D43: Baseline | E43: Year 1 | F43: Year 2 | G43: Year 3
...
